<?xml version="1.0" ?>
<!-- =================================================================================== -->
<!-- |    This document was autogenerated by xacro from /home/windiff/Code/Affordance-Guided-Interaction/Z1-Dingo-Robot/src/unidingo_description/urdf/uni_dingo_dual_arm.urdf.xacro | -->
<!-- |    EDITING THIS FILE BY HAND IS NOT RECOMMENDED                                 | -->
<!-- =================================================================================== -->
<!--
  Uni-Dingo 双臂机器人描述
  包含: Dingo 底盘 + 左 Z1 机械臂 + 右 Z1 机械臂 + Pan-Tilt 云台
-->
<robot name="uni_dingo_dual_arm">
  <material name="arm_support_grey">
    <color rgba="0.3 0.3 0.3 1.0"/>
  </material>
  <material name="dark_grey">
    <color rgba="0.2 0.2 0.2 1.0"/>
  </material>
  <material name="light_grey">
    <color rgba="0.4 0.4 0.4 1.0"/>
  </material>
  <material name="yellow">
    <color rgba="0.8 0.8 0.0 1.0"/>
  </material>
  <material name="black">
    <color rgba="0.15 0.15 0.15 1.0"/>
  </material>
  <link name="front_left_wheel_link">
    <visual>
      <origin rpy="1.5707963267948966 0 0" xyz="0 0 0"/>
      <geometry>
        <cylinder length="0.05" radius="0.05"/>
      </geometry>
      <material name="black"/>
    </visual>
    <collision>
      <origin rpy="1.5707963267948966 0 0" xyz="0 0 0"/>
      <geometry>
        <cylinder length="0.05" radius="0.05"/>
      </geometry>
    </collision>
    <inertial>
      <origin rpy="0 0 0" xyz="0 0 0"/>
      <mass value="0.4"/>
      <inertia ixx="0.0003234" ixy="0" ixz="0" iyy="0.0003234" iyz="0" izz="0.0004901"/>
    </inertial>
  </link>
  <joint name="front_left_wheel" type="continuous">
    <parent link="chassis_link"/>
    <child link="front_left_wheel_link"/>
    <origin rpy="0 0 0" xyz="0.285 0.2104 0.035145"/>
    <axis xyz="0 1 0"/>
  </joint>
  <transmission name="front_left_wheel_trans">
    <type>transmission_interface/SimpleTransmission</type>
    <joint name="front_left_wheel">
      <hardwareInterface>hardware_interface/VelocityJointInterface</hardwareInterface>
    </joint>
    <actuator name="front_left_actuator">
      <mechanicalReduction>1</mechanicalReduction>
    </actuator>
  </transmission>
  <link name="front_right_wheel_link">
    <visual>
      <origin rpy="1.5707963267948966 0 0" xyz="0 0 0"/>
      <geometry>
        <cylinder length="0.05" radius="0.05"/>
      </geometry>
      <material name="black"/>
    </visual>
    <collision>
      <origin rpy="1.5707963267948966 0 0" xyz="0 0 0"/>
      <geometry>
        <cylinder length="0.05" radius="0.05"/>
      </geometry>
    </collision>
    <inertial>
      <origin rpy="0 0 0" xyz="0 0 0"/>
      <mass value="0.4"/>
      <inertia ixx="0.0003234" ixy="0" ixz="0" iyy="0.0003234" iyz="0" izz="0.0004901"/>
    </inertial>
  </link>
  <joint name="front_right_wheel" type="continuous">
    <parent link="chassis_link"/>
    <child link="front_right_wheel_link"/>
    <origin rpy="0 0 0" xyz="0.285 -0.2104 0.035145"/>
    <axis xyz="0 1 0"/>
  </joint>
  <transmission name="front_right_wheel_trans">
    <type>transmission_interface/SimpleTransmission</type>
    <joint name="front_right_wheel">
      <hardwareInterface>hardware_interface/VelocityJointInterface</hardwareInterface>
    </joint>
    <actuator name="front_right_actuator">
      <mechanicalReduction>1</mechanicalReduction>
    </actuator>
  </transmission>
  <link name="rear_left_wheel_link">
    <visual>
      <origin rpy="1.5707963267948966 0 0" xyz="0 0 0"/>
      <geometry>
        <cylinder length="0.05" radius="0.05"/>
      </geometry>
      <material name="black"/>
    </visual>
    <collision>
      <origin rpy="1.5707963267948966 0 0" xyz="0 0 0"/>
      <geometry>
        <cylinder length="0.05" radius="0.05"/>
      </geometry>
    </collision>
    <inertial>
      <origin rpy="0 0 0" xyz="0 0 0"/>
      <mass value="0.4"/>
      <inertia ixx="0.0003234" ixy="0" ixz="0" iyy="0.0003234" iyz="0" izz="0.0004901"/>
    </inertial>
  </link>
  <joint name="rear_left_wheel" type="continuous">
    <parent link="chassis_link"/>
    <child link="rear_left_wheel_link"/>
    <origin rpy="0 0 0" xyz="-0.285 0.2104 0.035145"/>
    <axis xyz="0 1 0"/>
  </joint>
  <transmission name="rear_left_wheel_trans">
    <type>transmission_interface/SimpleTransmission</type>
    <joint name="rear_left_wheel">
      <hardwareInterface>hardware_interface/VelocityJointInterface</hardwareInterface>
    </joint>
    <actuator name="rear_left_actuator">
      <mechanicalReduction>1</mechanicalReduction>
    </actuator>
  </transmission>
  <link name="rear_right_wheel_link">
    <visual>
      <origin rpy="1.5707963267948966 0 0" xyz="0 0 0"/>
      <geometry>
        <cylinder length="0.05" radius="0.05"/>
      </geometry>
      <material name="black"/>
    </visual>
    <collision>
      <origin rpy="1.5707963267948966 0 0" xyz="0 0 0"/>
      <geometry>
        <cylinder length="0.05" radius="0.05"/>
      </geometry>
    </collision>
    <inertial>
      <origin rpy="0 0 0" xyz="0 0 0"/>
      <mass value="0.4"/>
      <inertia ixx="0.0003234" ixy="0" ixz="0" iyy="0.0003234" iyz="0" izz="0.0004901"/>
    </inertial>
  </link>
  <joint name="rear_right_wheel" type="continuous">
    <parent link="chassis_link"/>
    <child link="rear_right_wheel_link"/>
    <origin rpy="0 0 0" xyz="-0.285 -0.2104 0.035145"/>
    <axis xyz="0 1 0"/>
  </joint>
  <transmission name="rear_right_wheel_trans">
    <type>transmission_interface/SimpleTransmission</type>
    <joint name="rear_right_wheel">
      <hardwareInterface>hardware_interface/VelocityJointInterface</hardwareInterface>
    </joint>
    <actuator name="rear_right_actuator">
      <mechanicalReduction>1</mechanicalReduction>
    </actuator>
  </transmission>
  <link name="base_link"/>
  <joint name="base_link_joint" type="fixed">
    <origin rpy="0 0 0" xyz="0 0 0"/>
    <parent link="base_link"/>
    <child link="chassis_link"/>
  </joint>
  <link name="chassis_link">
    <visual>
      <origin rpy="0 0 0" xyz="0 0 0"/>
      <geometry>
        <mesh filename="file:///home/windiff/Code/Affordance-Guided-Interaction/assets/robot/meshes/dingo/omni_chassis.dae"/>
      </geometry>
      <material name="dark_grey"/>
    </visual>
    <collision>
      <origin xyz="0 0 0"/>
      <geometry>
        <mesh filename="file:///home/windiff/Code/Affordance-Guided-Interaction/assets/robot/meshes/dingo/omni_chassis_collision.stl"/>
      </geometry>
    </collision>
    <inertial>
      <!-- Center of mass -->
      <origin rpy="0 0 0" xyz="0 0 0"/>
      <mass value="14"/>
      <!-- Moments of inertia: ( chassis without wheels ) -->
      <inertia ixx="0.35498" ixy="0" ixz="0" iyy="0.7266" iyz="0" izz="1.0553"/>
    </inertial>
  </link>
  <link name="imu_link">
    <inertial>
      <mass value="0.001"/>
      <origin rpy="0 0 0" xyz="0 0 0"/>
      <inertia ixx="1e-09" ixy="0.0" ixz="0.0" iyy="1e-09" iyz="0.0" izz="1e-09"/>
    </inertial>
  </link>
  <joint name="imu_joint" type="fixed">
    <parent link="chassis_link"/>
    <child link="imu_link"/>
  </joint>
  <!--
    Mounting points for accessories in the top channel.
    These are flush with the top of the robot and all oriented to face forwards.
    Dingo-D has 6 evenly-spaced 80mm mounts
    We name the mounts (from front to back)
      - front
      - front b
      - front c
      - mid
      - rear c
      - rear b
      - rear
  -->
  <link name="front_mount"/>
  <link name="front_b_mount"/>
  <link name="front_c_mount"/>
  <link name="rear_mount"/>
  <link name="rear_b_mount"/>
  <link name="rear_c_mount"/>
  <link name="mid_mount"/>
  <joint name="mid_mount_joint" type="fixed">
    <origin rpy="0 0 0" xyz="0 0 0.069023"/>
    <parent link="chassis_link"/>
    <child link="mid_mount"/>
  </joint>
  <joint name="front_c_mount_joint" type="fixed">
    <origin rpy="0 0 0" xyz="0.080 0 0"/>
    <parent link="mid_mount"/>
    <child link="front_c_mount"/>
  </joint>
  <joint name="front_b_mount_joint" type="fixed">
    <origin rpy="0 0 0" xyz="0.080 0 0"/>
    <parent link="front_c_mount"/>
    <child link="front_b_mount"/>
  </joint>
  <joint name="front_mount_joint" type="fixed">
    <origin rpy="0 0 0" xyz="0.080 0 0"/>
    <parent link="front_b_mount"/>
    <child link="front_mount"/>
  </joint>
  <joint name="rear_c_mount_joint" type="fixed">
    <origin rpy="0 0 0" xyz="-0.080 0 0"/>
    <parent link="mid_mount"/>
    <child link="rear_c_mount"/>
  </joint>
  <joint name="rear_b_mount_joint" type="fixed">
    <origin rpy="0 0 0" xyz="-0.080 0 0"/>
    <parent link="rear_c_mount"/>
    <child link="rear_b_mount"/>
  </joint>
  <joint name="rear_moint_joint" type="fixed">
    <origin rpy="0 0 0" xyz="-0.080 0 0"/>
    <parent link="rear_b_mount"/>
    <child link="rear_mount"/>
  </joint>
  <!--
    Mounting point for accessories on the front bumper.
    Use with caution, but thin sensors (e.g Raspberry Pi NoIR camera) could
    be mounted here for low-budget, front/rear-facing capabilities
  -->
  <link name="front_bumper_mount"/>
  <joint name="front_bumper_mount_joint" type="fixed">
    <origin rpy="0 0 0" xyz="0.34159 0 0.0345115"/>
    <parent link="chassis_link"/>
    <child link="front_bumper_mount"/>
  </joint>
  <gazebo>
    <plugin filename="libgazebo_ros_control.so" name="gazebo_ros_control">
      <robotNamespace>/</robotNamespace>
    </plugin>
  </gazebo>
  <gazebo>
    <plugin filename="libhector_gazebo_ros_imu.so" name="imu_controller">
      <robotNamespace>/</robotNamespace>
      <updateRate>50.0</updateRate>
      <bodyName>imu_link</bodyName>
      <topicName>imu/data</topicName>
      <accelDrift>0.005 0.005 0.005</accelDrift>
      <accelGaussianNoise>0.005 0.005 0.005</accelGaussianNoise>
      <rateDrift>0.005 0.005 0.005 </rateDrift>
      <rateGaussianNoise>0.005 0.005 0.005 </rateGaussianNoise>
      <headingDrift>0.005</headingDrift>
      <headingGaussianNoise>0.005</headingGaussianNoise>
    </plugin>
  </gazebo>
  <gazebo reference="base_link">
    <turnGravityOff>false</turnGravityOff>
  </gazebo>
  <gazebo reference="chassis_link">
    <turnGravityOff>false</turnGravityOff>
  </gazebo>
  <gazebo reference="imu_link">
    <turnGravityOff>false</turnGravityOff>
  </gazebo>
  <gazebo>
    <plugin filename="libridgeback_ros_force_based_move.so" name="dingo_ros_force_based_move">
      <robotNamespace>/</robotNamespace>
      <commandTopic>dingo_velocity_controller/cmd_vel</commandTopic>
      <odometryTopic>odom</odometryTopic>
      <odometryFrame>odom</odometryFrame>
      <odometryRate>50.0</odometryRate>
      <robotBaseFrame>base_link</robotBaseFrame>
      <cmdVelTimeOut>0.25</cmdVelTimeOut>
      <!-- Don't publish a transform: the controller does it. -->
      <publishOdometryTf>0</publishOdometryTf>
      <yaw_velocity_p_gain>500.0</yaw_velocity_p_gain>
      <x_velocity_p_gain>10000.0</x_velocity_p_gain>
      <y_velocity_p_gain>10000.0</y_velocity_p_gain>
    </plugin>
  </gazebo>
  <gazebo reference="front_left_wheel_link">
    <material>Gazebo/DarkGrey</material>
    <mu1>0.0</mu1>
    <mu2>0.0</mu2>
  </gazebo>
  <gazebo reference="front_right_wheel_link">
    <material>Gazebo/DarkGrey</material>
    <mu1>0.0</mu1>
    <mu2>0.0</mu2>
  </gazebo>
  <gazebo reference="rear_left_wheel_link">
    <material>Gazebo/DarkGrey</material>
    <mu1>0.0</mu1>
    <mu2>0.0</mu2>
  </gazebo>
  <gazebo reference="rear_right_wheel_link">
    <material>Gazebo/DarkGrey</material>
    <mu1>0.0</mu1>
    <mu2>0.0</mu2>
  </gazebo>
  <!--
    As you add to this URDF, please be aware that both the robot and
    simulation include it. You must retain compatibility with all of
    the following launch files:

    dingo_viz/launch/view_model.launch
    dingo_gazebo/launch/dingo_world.launch
    dingo_base/launch/base.launch
  -->
  <!-- This file is a placeholder which is included by default from
       dingo.urdf.xacro. If a robot is being customized and requires
       additional URDF, set the DINGO_URDF_EXTRAS environment variable
       to the full path of the file you would like included. -->
  <!-- Enable self-collision for base links in Gazebo -->
  <gazebo reference="base_link">
    <self_collide>true</self_collide>
  </gazebo>
  <gazebo reference="chassis_link">
    <self_collide>true</self_collide>
  </gazebo>
  <!-- ========== 左臂安装座 + 支撑柱（合并为一个 link） ========== -->
  <link name="leftarm_link">
    <inertial>
      <origin rpy="0 0 0" xyz="0 0 -0.23614000000000002"/>
      <mass value="1.4"/>
      <inertia ixx="0.02616231314666667" ixy="0" ixz="0" iyy="0.02616231314666667" iyz="0" izz="0.00028"/>
    </inertial>
    <visual>
      <origin rpy="0 0 0" xyz="0 0 -0.23614000000000002"/>
      <geometry>
        <cylinder length="0.47228000000000003" radius="0.02"/>
      </geometry>
      <material name="arm_support_grey"/>
    </visual>
    <collision>
      <origin rpy="0 0 0" xyz="0 0 -0.23614000000000002"/>
      <geometry>
        <cylinder length="0.47228000000000003" radius="0.02"/>
      </geometry>
    </collision>
  </link>
  <joint name="base_leftarm_joint" type="fixed">
    <origin rpy="0 0 0" xyz="0.15091 0.11708 0.57228"/>
    <parent link="base_link"/>
    <child link="leftarm_link"/>
  </joint>
  <!-- ========== 右臂安装座 + 支撑柱（合并为一个 link） ========== -->
  <link name="rightarm_link">
    <inertial>
      <origin rpy="0 0 0" xyz="0 0 -0.23614000000000002"/>
      <mass value="1.4"/>
      <inertia ixx="0.02616231314666667" ixy="0" ixz="0" iyy="0.02616231314666667" iyz="0" izz="0.00028"/>
    </inertial>
    <visual>
      <origin rpy="0 0 0" xyz="0 0 -0.23614000000000002"/>
      <geometry>
        <cylinder length="0.47228000000000003" radius="0.02"/>
      </geometry>
      <material name="arm_support_grey"/>
    </visual>
    <collision>
      <origin rpy="0 0 0" xyz="0 0 -0.23614000000000002"/>
      <geometry>
        <cylinder length="0.47228000000000003" radius="0.02"/>
      </geometry>
    </collision>
  </link>
  <joint name="base_rightarm_joint" type="fixed">
    <origin rpy="0 0 0" xyz="0.15091 -0.11708 0.57228"/>
    <parent link="base_link"/>
    <child link="rightarm_link"/>
  </joint>
  <!-- 基座连接到父 link -->
  <joint name="left_base_joint" type="fixed">
    <origin rpy="0 0 0" xyz="0 0 0"/>
    <parent link="leftarm_link"/>
    <child link="left_link00"/>
  </joint>
  <!-- Link 00 - 底座 -->
  <link name="left_link00">
    <visual>
      <origin rpy="0 0 0" xyz="0 0 0"/>
      <geometry>
        <mesh filename="file:///home/windiff/Code/Affordance-Guided-Interaction/assets/robot/meshes/z1/visual/z1_Link00.dae" scale="1 1 1"/>
      </geometry>
    </visual>
    <collision>
      <geometry>
        <cylinder length="0.051" radius="0.0325"/>
      </geometry>
      <origin rpy="0 0 0" xyz="0 0 0.0255"/>
    </collision>
    <inertial>
      <origin rpy="0 0 0" xyz="-0.00334984 -0.00013615 0.02495843"/>
      <mass value="0.47247481"/>
      <inertia ixx="0.00037937" ixy="3.5e-07" ixz="1.037e-05" iyy="0.00041521" iyz="9.9e-07" izz="0.00053066"/>
    </inertial>
  </link>
  <!-- Joint 1 -->
  <joint name="left_joint1" type="revolute">
    <origin rpy="0 0 0" xyz="0 0 0.0585"/>
    <parent link="left_link00"/>
    <child link="left_link01"/>
    <axis xyz="0 0 1"/>
    <dynamics damping="1.0" friction="1.0"/>
    <limit effort="30.0" lower="-2.6179938779914944" upper="2.6179938779914944" velocity="3.1415"/>
  </joint>
  <!-- Link 01 -->
  <link name="left_link01">
    <visual>
      <origin rpy="0 0 0" xyz="0 0 0"/>
      <geometry>
        <mesh filename="file:///home/windiff/Code/Affordance-Guided-Interaction/assets/robot/meshes/z1/visual/z1_Link01.dae" scale="1 1 1"/>
      </geometry>
    </visual>
    <collision>
      <origin rpy="0 0 0" xyz="0 0 0"/>
      <geometry>
        <mesh filename="file:///home/windiff/Code/Affordance-Guided-Interaction/assets/robot/meshes/z1/collision/z1_Link01.STL" scale="1 1 1"/>
      </geometry>
    </collision>
    <inertial>
      <origin rpy="0 0 0" xyz="2.47e-06 -0.00025198 0.02317169"/>
      <mass value="0.67332551"/>
      <inertia ixx="0.00128328" ixy="6e-08" ixz="4e-07" iyy="0.00071931" iyz="-5e-07" izz="0.00083936"/>
    </inertial>
  </link>
  <!-- Joint 2 -->
  <joint name="left_joint2" type="revolute">
    <origin rpy="0 0 0" xyz="0 0 0.045"/>
    <parent link="left_link01"/>
    <child link="left_link02"/>
    <axis xyz="0 1 0"/>
    <dynamics damping="2.0" friction="2.0"/>
    <limit effort="60.0" lower="0.0" upper="2.9670597283903604" velocity="3.1415"/>
  </joint>
  <!-- Link 02 -->
  <link name="left_link02">
    <visual>
      <origin rpy="0 0 0" xyz="0 0 0"/>
      <geometry>
        <mesh filename="file:///home/windiff/Code/Affordance-Guided-Interaction/assets/robot/meshes/z1/visual/z1_Link02.dae" scale="1 1 1"/>
      </geometry>
    </visual>
    <collision>
      <geometry>
        <cylinder length="0.102" radius="0.0325"/>
      </geometry>
      <origin rpy="1.5707963267948966 0 0" xyz="0 0 0"/>
    </collision>
    <collision>
      <geometry>
        <cylinder length="0.235" radius="0.0225"/>
      </geometry>
      <origin rpy="0 1.5707963267948966 0" xyz="-0.16249999999999998 0 0"/>
    </collision>
    <collision>
      <geometry>
        <cylinder length="0.051" radius="0.0325"/>
      </geometry>
      <origin rpy="1.5707963267948966 0 0" xyz="-0.35 0 0"/>
    </collision>
    <inertial>
      <origin rpy="0 0 0" xyz="-0.11012601 0.00240029 0.00158266"/>
      <mass value="1.19132258"/>
      <inertia ixx="0.00102138" ixy="-0.00062358" ixz="-5.13e-06" iyy="0.02429457" iyz="2.1e-06" izz="0.02466114"/>
    </inertial>
  </link>
  <!-- Joint 3 -->
  <joint name="left_joint3" type="revolute">
    <origin rpy="0 0 0" xyz="-0.35 0 0"/>
    <parent link="left_link02"/>
    <child link="left_link03"/>
    <axis xyz="0 1 0"/>
    <dynamics damping="1.0" friction="1.0"/>
    <limit effort="30.0" lower="-2.8797932657906435" upper="0.0" velocity="3.1415"/>
  </joint>
  <!-- Link 03 -->
  <link name="left_link03">
    <visual>
      <origin rpy="0 0 0" xyz="0 0 0"/>
      <geometry>
        <mesh filename="file:///home/windiff/Code/Affordance-Guided-Interaction/assets/robot/meshes/z1/visual/z1_Link03.dae" scale="1 1 1"/>
      </geometry>
    </visual>
    <collision>
      <geometry>
        <cylinder length="0.116" radius="0.02"/>
      </geometry>
      <origin rpy="0 1.5707963267948966 0" xyz="0.128 0 0.055"/>
    </collision>
    <collision>
      <geometry>
        <cylinder length="0.059" radius="0.0325"/>
      </geometry>
      <origin rpy="0 1.5707963267948966 1.5707963267948966" xyz="0.2205 0 0.055"/>
    </collision>
    <inertial>
      <origin rpy="0 0 0" xyz="0.10609208 -0.00541815 0.03476383"/>
      <mass value="0.83940874"/>
      <inertia ixx="0.00108061" ixy="8.669e-05" ixz="0.00208102" iyy="0.00954238" iyz="1.332e-05" izz="0.00886621"/>
    </inertial>
  </link>
  <!-- Joint 4 -->
  <joint name="left_joint4" type="revolute">
    <origin rpy="0 0 0" xyz="0.218 0 0.057"/>
    <parent link="left_link03"/>
    <child link="left_link04"/>
    <axis xyz="0 1 0"/>
    <dynamics damping="1.0" friction="1.0"/>
    <limit effort="30.0" lower="-1.5184364492350666" upper="1.5184364492350666" velocity="3.1415"/>
  </joint>
  <!-- Link 04 -->
  <link name="left_link04">
    <visual>
      <origin rpy="0 0 0" xyz="0 0 0"/>
      <geometry>
        <mesh filename="file:///home/windiff/Code/Affordance-Guided-Interaction/assets/robot/meshes/z1/visual/z1_Link04.dae" scale="1 1 1"/>
      </geometry>
    </visual>
    <collision>
      <geometry>
        <cylinder length="0.067" radius="0.0325"/>
      </geometry>
      <origin rpy="0 0 0" xyz="0.072 0 0"/>
    </collision>
    <inertial>
      <origin rpy="0 0 0" xyz="0.04366681 0.00364738 -0.00170192"/>
      <mass value="0.56404563"/>
      <inertia ixx="0.00031576" ixy="-8.13e-05" ixz="-4.091e-05" iyy="0.00092996" iyz="5.96e-06" izz="0.00097912"/>
    </inertial>
  </link>
  <!-- Joint 5 -->
  <joint name="left_joint5" type="revolute">
    <origin rpy="0 0 0" xyz="0.07 0.0 0.0"/>
    <parent link="left_link04"/>
    <child link="left_link05"/>
    <axis xyz="0 0 1"/>
    <dynamics damping="1.0" friction="1.0"/>
    <limit effort="30.0" lower="-1.3439035240356338" upper="1.3439035240356338" velocity="3.1415"/>
  </joint>
  <!-- Link 05 -->
  <link name="left_link05">
    <visual>
      <origin rpy="0 0 0" xyz="0 0 0"/>
      <geometry>
        <mesh filename="file:///home/windiff/Code/Affordance-Guided-Interaction/assets/robot/meshes/z1/visual/z1_Link05.dae" scale="1 1 1"/>
      </geometry>
    </visual>
    <collision>
      <origin rpy="0 0 0" xyz="0 0 0"/>
      <geometry>
        <mesh filename="file:///home/windiff/Code/Affordance-Guided-Interaction/assets/robot/meshes/z1/collision/z1_Link05.STL" scale="1 1 1"/>
      </geometry>
    </collision>
    <inertial>
      <origin rpy="0 0 0" xyz="0.03121533 0.0 0.00646316"/>
      <mass value="0.38938492"/>
      <inertia ixx="0.00017605" ixy="-4e-07" ixz="-5.689e-05" iyy="0.00055896" iyz="1.3e-07" izz="0.0005386"/>
    </inertial>
  </link>
  <!-- Joint 6 -->
  <joint name="left_joint6" type="revolute">
    <origin rpy="0 0 0" xyz="0.0492 0.0 0.0"/>
    <parent link="left_link05"/>
    <child link="left_link06"/>
    <axis xyz="1 0 0"/>
    <dynamics damping="1.0" friction="1.0"/>
    <limit effort="30.0" lower="-2.792526803190927" upper="2.792526803190927" velocity="3.1415"/>
  </joint>
  <!-- Link 06 -->
  <link name="left_link06">
    <visual>
      <origin rpy="0 0 0" xyz="0 0 0"/>
      <geometry>
        <mesh filename="file:///home/windiff/Code/Affordance-Guided-Interaction/assets/robot/meshes/z1/visual/z1_Link06.dae" scale="1 1 1"/>
      </geometry>
    </visual>
    <collision>
      <geometry>
        <cylinder length="0.051" radius="0.0325"/>
      </geometry>
      <origin rpy="0 1.5707963267948966 0" xyz="0.0255 0 0"/>
    </collision>
    <inertial>
      <origin rpy="0 0 0" xyz="0.0241569 -0.00017355 -0.00143876"/>
      <mass value="0.28875807"/>
      <inertia ixx="0.00018328" ixy="-1.22e-06" ixz="-5.4e-07" iyy="0.0001475" iyz="-8e-08" izz="0.0001468"/>
    </inertial>
  </link>
  <joint name="left_gripperStator_joint" type="fixed">
    <origin rpy="0 0 0" xyz="0.051 0.0 0.0"/>
    <parent link="left_link06"/>
    <child link="left_gripperStator"/>
  </joint>
  <link name="left_gripperStator">
    <visual>
      <geometry>
        <mesh filename="file:///home/windiff/Code/Affordance-Guided-Interaction/assets/robot/meshes/z1/visual/z1_GripperStator.dae" scale="1 1 1"/>
      </geometry>
    </visual>
    <collision>
      <geometry>
        <mesh filename="file:///home/windiff/Code/Affordance-Guided-Interaction/assets/robot/meshes/z1/collision/z1_GripperStator.STL" scale="1 1 1"/>
      </geometry>
    </collision>
    <inertial>
      <origin rpy="0 0 0" xyz="0.04764427 -0.00035819 -0.00249162"/>
      <mass value="0.52603655"/>
      <inertia ixx="0.00038683" ixy="3.59e-06" ixz="-7.662e-05" iyy="0.00068614" iyz="-2.09e-06" izz="0.00066293"/>
    </inertial>
  </link>
  <joint name="left_jointGripper" type="revolute">
    <origin rpy="0 0 0" xyz="0.049 0.0 0"/>
    <parent link="left_gripperStator"/>
    <child link="left_gripperMover"/>
    <axis xyz="0 1 0"/>
    <dynamics damping="1.0" friction="1.0"/>
    <limit effort="30.0" lower="-1.5707963267948966" upper="0.0" velocity="3.1415"/>
  </joint>
  <link name="left_gripperMover">
    <visual>
      <geometry>
        <mesh filename="file:///home/windiff/Code/Affordance-Guided-Interaction/assets/robot/meshes/z1/visual/z1_GripperMover.dae" scale="1 1 1"/>
      </geometry>
    </visual>
    <collision>
      <geometry>
        <mesh filename="file:///home/windiff/Code/Affordance-Guided-Interaction/assets/robot/meshes/z1/collision/z1_GripperMover.STL" scale="1 1 1"/>
      </geometry>
    </collision>
    <inertial>
      <origin rpy="0 0 0" xyz="0.01320633 0.00476708 0.00380534"/>
      <mass value="0.27621302"/>
      <inertia ixx="0.00017716" ixy="-1.683e-05" ixz="1.786e-05" iyy="0.00026787" iyz="-2.62e-06" izz="0.00035728"/>
    </inertial>
  </link>
  <transmission name="left_trans_jointGripper">
    <type>transmission_interface/SimpleTransmission</type>
    <joint name="left_jointGripper">
      <hardwareInterface>hardware_interface/PositionJointInterface</hardwareInterface>
    </joint>
    <actuator name="left_motorGripper">
      <hardwareInterface>hardware_interface/PositionJointInterface</hardwareInterface>
      <mechanicalReduction>1</mechanicalReduction>
    </actuator>
  </transmission>
  <gazebo reference="left_gripperStator">
    <self_collide>true</self_collide>
  </gazebo>
  <gazebo reference="left_gripperMover">
    <self_collide>true</self_collide>
  </gazebo>
  <transmission name="left_trans_joint1">
    <type>transmission_interface/SimpleTransmission</type>
    <joint name="left_joint1">
      <hardwareInterface>hardware_interface/PositionJointInterface</hardwareInterface>
    </joint>
    <actuator name="left_motor1">
      <hardwareInterface>hardware_interface/PositionJointInterface</hardwareInterface>
      <mechanicalReduction>1</mechanicalReduction>
    </actuator>
  </transmission>
  <transmission name="left_trans_joint2">
    <type>transmission_interface/SimpleTransmission</type>
    <joint name="left_joint2">
      <hardwareInterface>hardware_interface/PositionJointInterface</hardwareInterface>
    </joint>
    <actuator name="left_motor2">
      <hardwareInterface>hardware_interface/PositionJointInterface</hardwareInterface>
      <mechanicalReduction>1</mechanicalReduction>
    </actuator>
  </transmission>
  <transmission name="left_trans_joint3">
    <type>transmission_interface/SimpleTransmission</type>
    <joint name="left_joint3">
      <hardwareInterface>hardware_interface/PositionJointInterface</hardwareInterface>
    </joint>
    <actuator name="left_motor3">
      <hardwareInterface>hardware_interface/PositionJointInterface</hardwareInterface>
      <mechanicalReduction>1</mechanicalReduction>
    </actuator>
  </transmission>
  <transmission name="left_trans_joint4">
    <type>transmission_interface/SimpleTransmission</type>
    <joint name="left_joint4">
      <hardwareInterface>hardware_interface/PositionJointInterface</hardwareInterface>
    </joint>
    <actuator name="left_motor4">
      <hardwareInterface>hardware_interface/PositionJointInterface</hardwareInterface>
      <mechanicalReduction>1</mechanicalReduction>
    </actuator>
  </transmission>
  <transmission name="left_trans_joint5">
    <type>transmission_interface/SimpleTransmission</type>
    <joint name="left_joint5">
      <hardwareInterface>hardware_interface/PositionJointInterface</hardwareInterface>
    </joint>
    <actuator name="left_motor5">
      <hardwareInterface>hardware_interface/PositionJointInterface</hardwareInterface>
      <mechanicalReduction>1</mechanicalReduction>
    </actuator>
  </transmission>
  <transmission name="left_trans_joint6">
    <type>transmission_interface/SimpleTransmission</type>
    <joint name="left_joint6">
      <hardwareInterface>hardware_interface/PositionJointInterface</hardwareInterface>
    </joint>
    <actuator name="left_motor6">
      <hardwareInterface>hardware_interface/PositionJointInterface</hardwareInterface>
      <mechanicalReduction>1</mechanicalReduction>
    </actuator>
  </transmission>
  <!-- Enable self-collision in Gazebo for arm links -->
  <gazebo reference="left_link00">
    <self_collide>true</self_collide>
  </gazebo>
  <gazebo reference="left_link01">
    <self_collide>true</self_collide>
  </gazebo>
  <gazebo reference="left_link02">
    <self_collide>true</self_collide>
  </gazebo>
  <gazebo reference="left_link03">
    <self_collide>true</self_collide>
  </gazebo>
  <gazebo reference="left_link04">
    <self_collide>true</self_collide>
  </gazebo>
  <gazebo reference="left_link05">
    <self_collide>true</self_collide>
  </gazebo>
  <gazebo reference="left_link06">
    <self_collide>true</self_collide>
  </gazebo>
  <!-- 基座连接到父 link -->
  <joint name="right_base_joint" type="fixed">
    <origin rpy="0 0 0" xyz="0 0 0"/>
    <parent link="rightarm_link"/>
    <child link="right_link00"/>
  </joint>
  <!-- Link 00 - 底座 -->
  <link name="right_link00">
    <visual>
      <origin rpy="0 0 0" xyz="0 0 0"/>
      <geometry>
        <mesh filename="file:///home/windiff/Code/Affordance-Guided-Interaction/assets/robot/meshes/z1/visual/z1_Link00.dae" scale="1 1 1"/>
      </geometry>
    </visual>
    <collision>
      <geometry>
        <cylinder length="0.051" radius="0.0325"/>
      </geometry>
      <origin rpy="0 0 0" xyz="0 0 0.0255"/>
    </collision>
    <inertial>
      <origin rpy="0 0 0" xyz="-0.00334984 -0.00013615 0.02495843"/>
      <mass value="0.47247481"/>
      <inertia ixx="0.00037937" ixy="3.5e-07" ixz="1.037e-05" iyy="0.00041521" iyz="9.9e-07" izz="0.00053066"/>
    </inertial>
  </link>
  <!-- Joint 1 -->
  <joint name="right_joint1" type="revolute">
    <origin rpy="0 0 0" xyz="0 0 0.0585"/>
    <parent link="right_link00"/>
    <child link="right_link01"/>
    <axis xyz="0 0 1"/>
    <dynamics damping="1.0" friction="1.0"/>
    <limit effort="30.0" lower="-2.6179938779914944" upper="2.6179938779914944" velocity="3.1415"/>
  </joint>
  <!-- Link 01 -->
  <link name="right_link01">
    <visual>
      <origin rpy="0 0 0" xyz="0 0 0"/>
      <geometry>
        <mesh filename="file:///home/windiff/Code/Affordance-Guided-Interaction/assets/robot/meshes/z1/visual/z1_Link01.dae" scale="1 1 1"/>
      </geometry>
    </visual>
    <collision>
      <origin rpy="0 0 0" xyz="0 0 0"/>
      <geometry>
        <mesh filename="file:///home/windiff/Code/Affordance-Guided-Interaction/assets/robot/meshes/z1/collision/z1_Link01.STL" scale="1 1 1"/>
      </geometry>
    </collision>
    <inertial>
      <origin rpy="0 0 0" xyz="2.47e-06 -0.00025198 0.02317169"/>
      <mass value="0.67332551"/>
      <inertia ixx="0.00128328" ixy="6e-08" ixz="4e-07" iyy="0.00071931" iyz="-5e-07" izz="0.00083936"/>
    </inertial>
  </link>
  <!-- Joint 2 -->
  <joint name="right_joint2" type="revolute">
    <origin rpy="0 0 0" xyz="0 0 0.045"/>
    <parent link="right_link01"/>
    <child link="right_link02"/>
    <axis xyz="0 1 0"/>
    <dynamics damping="2.0" friction="2.0"/>
    <limit effort="60.0" lower="0.0" upper="2.9670597283903604" velocity="3.1415"/>
  </joint>
  <!-- Link 02 -->
  <link name="right_link02">
    <visual>
      <origin rpy="0 0 0" xyz="0 0 0"/>
      <geometry>
        <mesh filename="file:///home/windiff/Code/Affordance-Guided-Interaction/assets/robot/meshes/z1/visual/z1_Link02.dae" scale="1 1 1"/>
      </geometry>
    </visual>
    <collision>
      <geometry>
        <cylinder length="0.102" radius="0.0325"/>
      </geometry>
      <origin rpy="1.5707963267948966 0 0" xyz="0 0 0"/>
    </collision>
    <collision>
      <geometry>
        <cylinder length="0.235" radius="0.0225"/>
      </geometry>
      <origin rpy="0 1.5707963267948966 0" xyz="-0.16249999999999998 0 0"/>
    </collision>
    <collision>
      <geometry>
        <cylinder length="0.051" radius="0.0325"/>
      </geometry>
      <origin rpy="1.5707963267948966 0 0" xyz="-0.35 0 0"/>
    </collision>
    <inertial>
      <origin rpy="0 0 0" xyz="-0.11012601 0.00240029 0.00158266"/>
      <mass value="1.19132258"/>
      <inertia ixx="0.00102138" ixy="-0.00062358" ixz="-5.13e-06" iyy="0.02429457" iyz="2.1e-06" izz="0.02466114"/>
    </inertial>
  </link>
  <!-- Joint 3 -->
  <joint name="right_joint3" type="revolute">
    <origin rpy="0 0 0" xyz="-0.35 0 0"/>
    <parent link="right_link02"/>
    <child link="right_link03"/>
    <axis xyz="0 1 0"/>
    <dynamics damping="1.0" friction="1.0"/>
    <limit effort="30.0" lower="-2.8797932657906435" upper="0.0" velocity="3.1415"/>
  </joint>
  <!-- Link 03 -->
  <link name="right_link03">
    <visual>
      <origin rpy="0 0 0" xyz="0 0 0"/>
      <geometry>
        <mesh filename="file:///home/windiff/Code/Affordance-Guided-Interaction/assets/robot/meshes/z1/visual/z1_Link03.dae" scale="1 1 1"/>
      </geometry>
    </visual>
    <collision>
      <geometry>
        <cylinder length="0.116" radius="0.02"/>
      </geometry>
      <origin rpy="0 1.5707963267948966 0" xyz="0.128 0 0.055"/>
    </collision>
    <collision>
      <geometry>
        <cylinder length="0.059" radius="0.0325"/>
      </geometry>
      <origin rpy="0 1.5707963267948966 1.5707963267948966" xyz="0.2205 0 0.055"/>
    </collision>
    <inertial>
      <origin rpy="0 0 0" xyz="0.10609208 -0.00541815 0.03476383"/>
      <mass value="0.83940874"/>
      <inertia ixx="0.00108061" ixy="8.669e-05" ixz="0.00208102" iyy="0.00954238" iyz="1.332e-05" izz="0.00886621"/>
    </inertial>
  </link>
  <!-- Joint 4 -->
  <joint name="right_joint4" type="revolute">
    <origin rpy="0 0 0" xyz="0.218 0 0.057"/>
    <parent link="right_link03"/>
    <child link="right_link04"/>
    <axis xyz="0 1 0"/>
    <dynamics damping="1.0" friction="1.0"/>
    <limit effort="30.0" lower="-1.5184364492350666" upper="1.5184364492350666" velocity="3.1415"/>
  </joint>
  <!-- Link 04 -->
  <link name="right_link04">
    <visual>
      <origin rpy="0 0 0" xyz="0 0 0"/>
      <geometry>
        <mesh filename="file:///home/windiff/Code/Affordance-Guided-Interaction/assets/robot/meshes/z1/visual/z1_Link04.dae" scale="1 1 1"/>
      </geometry>
    </visual>
    <collision>
      <geometry>
        <cylinder length="0.067" radius="0.0325"/>
      </geometry>
      <origin rpy="0 0 0" xyz="0.072 0 0"/>
    </collision>
    <inertial>
      <origin rpy="0 0 0" xyz="0.04366681 0.00364738 -0.00170192"/>
      <mass value="0.56404563"/>
      <inertia ixx="0.00031576" ixy="-8.13e-05" ixz="-4.091e-05" iyy="0.00092996" iyz="5.96e-06" izz="0.00097912"/>
    </inertial>
  </link>
  <!-- Joint 5 -->
  <joint name="right_joint5" type="revolute">
    <origin rpy="0 0 0" xyz="0.07 0.0 0.0"/>
    <parent link="right_link04"/>
    <child link="right_link05"/>
    <axis xyz="0 0 1"/>
    <dynamics damping="1.0" friction="1.0"/>
    <limit effort="30.0" lower="-1.3439035240356338" upper="1.3439035240356338" velocity="3.1415"/>
  </joint>
  <!-- Link 05 -->
  <link name="right_link05">
    <visual>
      <origin rpy="0 0 0" xyz="0 0 0"/>
      <geometry>
        <mesh filename="file:///home/windiff/Code/Affordance-Guided-Interaction/assets/robot/meshes/z1/visual/z1_Link05.dae" scale="1 1 1"/>
      </geometry>
    </visual>
    <collision>
      <origin rpy="0 0 0" xyz="0 0 0"/>
      <geometry>
        <mesh filename="file:///home/windiff/Code/Affordance-Guided-Interaction/assets/robot/meshes/z1/collision/z1_Link05.STL" scale="1 1 1"/>
      </geometry>
    </collision>
    <inertial>
      <origin rpy="0 0 0" xyz="0.03121533 0.0 0.00646316"/>
      <mass value="0.38938492"/>
      <inertia ixx="0.00017605" ixy="-4e-07" ixz="-5.689e-05" iyy="0.00055896" iyz="1.3e-07" izz="0.0005386"/>
    </inertial>
  </link>
  <!-- Joint 6 -->
  <joint name="right_joint6" type="revolute">
    <origin rpy="0 0 0" xyz="0.0492 0.0 0.0"/>
    <parent link="right_link05"/>
    <child link="right_link06"/>
    <axis xyz="1 0 0"/>
    <dynamics damping="1.0" friction="1.0"/>
    <limit effort="30.0" lower="-2.792526803190927" upper="2.792526803190927" velocity="3.1415"/>
  </joint>
  <!-- Link 06 -->
  <link name="right_link06">
    <visual>
      <origin rpy="0 0 0" xyz="0 0 0"/>
      <geometry>
        <mesh filename="file:///home/windiff/Code/Affordance-Guided-Interaction/assets/robot/meshes/z1/visual/z1_Link06.dae" scale="1 1 1"/>
      </geometry>
    </visual>
    <collision>
      <geometry>
        <cylinder length="0.051" radius="0.0325"/>
      </geometry>
      <origin rpy="0 1.5707963267948966 0" xyz="0.0255 0 0"/>
    </collision>
    <inertial>
      <origin rpy="0 0 0" xyz="0.0241569 -0.00017355 -0.00143876"/>
      <mass value="0.28875807"/>
      <inertia ixx="0.00018328" ixy="-1.22e-06" ixz="-5.4e-07" iyy="0.0001475" iyz="-8e-08" izz="0.0001468"/>
    </inertial>
  </link>
  <joint name="right_gripperStator_joint" type="fixed">
    <origin rpy="0 0 0" xyz="0.051 0.0 0.0"/>
    <parent link="right_link06"/>
    <child link="right_gripperStator"/>
  </joint>
  <link name="right_gripperStator">
    <visual>
      <geometry>
        <mesh filename="file:///home/windiff/Code/Affordance-Guided-Interaction/assets/robot/meshes/z1/visual/z1_GripperStator.dae" scale="1 1 1"/>
      </geometry>
    </visual>
    <collision>
      <geometry>
        <mesh filename="file:///home/windiff/Code/Affordance-Guided-Interaction/assets/robot/meshes/z1/collision/z1_GripperStator.STL" scale="1 1 1"/>
      </geometry>
    </collision>
    <inertial>
      <origin rpy="0 0 0" xyz="0.04764427 -0.00035819 -0.00249162"/>
      <mass value="0.52603655"/>
      <inertia ixx="0.00038683" ixy="3.59e-06" ixz="-7.662e-05" iyy="0.00068614" iyz="-2.09e-06" izz="0.00066293"/>
    </inertial>
  </link>
  <joint name="right_jointGripper" type="revolute">
    <origin rpy="0 0 0" xyz="0.049 0.0 0"/>
    <parent link="right_gripperStator"/>
    <child link="right_gripperMover"/>
    <axis xyz="0 1 0"/>
    <dynamics damping="1.0" friction="1.0"/>
    <limit effort="30.0" lower="-1.5707963267948966" upper="0.0" velocity="3.1415"/>
  </joint>
  <link name="right_gripperMover">
    <visual>
      <geometry>
        <mesh filename="file:///home/windiff/Code/Affordance-Guided-Interaction/assets/robot/meshes/z1/visual/z1_GripperMover.dae" scale="1 1 1"/>
      </geometry>
    </visual>
    <collision>
      <geometry>
        <mesh filename="file:///home/windiff/Code/Affordance-Guided-Interaction/assets/robot/meshes/z1/collision/z1_GripperMover.STL" scale="1 1 1"/>
      </geometry>
    </collision>
    <inertial>
      <origin rpy="0 0 0" xyz="0.01320633 0.00476708 0.00380534"/>
      <mass value="0.27621302"/>
      <inertia ixx="0.00017716" ixy="-1.683e-05" ixz="1.786e-05" iyy="0.00026787" iyz="-2.62e-06" izz="0.00035728"/>
    </inertial>
  </link>
  <transmission name="right_trans_jointGripper">
    <type>transmission_interface/SimpleTransmission</type>
    <joint name="right_jointGripper">
      <hardwareInterface>hardware_interface/PositionJointInterface</hardwareInterface>
    </joint>
    <actuator name="right_motorGripper">
      <hardwareInterface>hardware_interface/PositionJointInterface</hardwareInterface>
      <mechanicalReduction>1</mechanicalReduction>
    </actuator>
  </transmission>
  <gazebo reference="right_gripperStator">
    <self_collide>true</self_collide>
  </gazebo>
  <gazebo reference="right_gripperMover">
    <self_collide>true</self_collide>
  </gazebo>
  <transmission name="right_trans_joint1">
    <type>transmission_interface/SimpleTransmission</type>
    <joint name="right_joint1">
      <hardwareInterface>hardware_interface/PositionJointInterface</hardwareInterface>
    </joint>
    <actuator name="right_motor1">
      <hardwareInterface>hardware_interface/PositionJointInterface</hardwareInterface>
      <mechanicalReduction>1</mechanicalReduction>
    </actuator>
  </transmission>
  <transmission name="right_trans_joint2">
    <type>transmission_interface/SimpleTransmission</type>
    <joint name="right_joint2">
      <hardwareInterface>hardware_interface/PositionJointInterface</hardwareInterface>
    </joint>
    <actuator name="right_motor2">
      <hardwareInterface>hardware_interface/PositionJointInterface</hardwareInterface>
      <mechanicalReduction>1</mechanicalReduction>
    </actuator>
  </transmission>
  <transmission name="right_trans_joint3">
    <type>transmission_interface/SimpleTransmission</type>
    <joint name="right_joint3">
      <hardwareInterface>hardware_interface/PositionJointInterface</hardwareInterface>
    </joint>
    <actuator name="right_motor3">
      <hardwareInterface>hardware_interface/PositionJointInterface</hardwareInterface>
      <mechanicalReduction>1</mechanicalReduction>
    </actuator>
  </transmission>
  <transmission name="right_trans_joint4">
    <type>transmission_interface/SimpleTransmission</type>
    <joint name="right_joint4">
      <hardwareInterface>hardware_interface/PositionJointInterface</hardwareInterface>
    </joint>
    <actuator name="right_motor4">
      <hardwareInterface>hardware_interface/PositionJointInterface</hardwareInterface>
      <mechanicalReduction>1</mechanicalReduction>
    </actuator>
  </transmission>
  <transmission name="right_trans_joint5">
    <type>transmission_interface/SimpleTransmission</type>
    <joint name="right_joint5">
      <hardwareInterface>hardware_interface/PositionJointInterface</hardwareInterface>
    </joint>
    <actuator name="right_motor5">
      <hardwareInterface>hardware_interface/PositionJointInterface</hardwareInterface>
      <mechanicalReduction>1</mechanicalReduction>
    </actuator>
  </transmission>
  <transmission name="right_trans_joint6">
    <type>transmission_interface/SimpleTransmission</type>
    <joint name="right_joint6">
      <hardwareInterface>hardware_interface/PositionJointInterface</hardwareInterface>
    </joint>
    <actuator name="right_motor6">
      <hardwareInterface>hardware_interface/PositionJointInterface</hardwareInterface>
      <mechanicalReduction>1</mechanicalReduction>
    </actuator>
  </transmission>
  <!-- Enable self-collision in Gazebo for arm links -->
  <gazebo reference="right_link00">
    <self_collide>true</self_collide>
  </gazebo>
  <gazebo reference="right_link01">
    <self_collide>true</self_collide>
  </gazebo>
  <gazebo reference="right_link02">
    <self_collide>true</self_collide>
  </gazebo>
  <gazebo reference="right_link03">
    <self_collide>true</self_collide>
  </gazebo>
  <gazebo reference="right_link04">
    <self_collide>true</self_collide>
  </gazebo>
  <gazebo reference="right_link05">
    <self_collide>true</self_collide>
  </gazebo>
  <gazebo reference="right_link06">
    <self_collide>true</self_collide>
  </gazebo>
  <!-- 云台安装座 + 支撑柱（合并为一个 link，云台挂载到此 link） -->
  <link name="pan_tilt_mount_link">
    <inertial>
      <origin rpy="0 0 0" xyz="0 0 -0.45"/>
      <mass value="2.7"/>
      <inertia ixx="0.18252000000000002" ixy="0" ixz="0" iyy="0.18252000000000002" iyz="0" izz="0.0005400000000000001"/>
    </inertial>
    <visual>
      <origin rpy="0 0 0" xyz="0 0 -0.45"/>
      <geometry>
        <cylinder length="0.9" radius="0.02"/>
      </geometry>
      <material name="arm_support_grey"/>
    </visual>
    <collision>
      <origin rpy="0 0 0" xyz="0 0 -0.45"/>
      <geometry>
        <cylinder length="0.9" radius="0.02"/>
      </geometry>
    </collision>
  </link>
  <joint name="base_pan_tilt_mount_joint" type="fixed">
    <origin rpy="0 0 0" xyz="0.15091 0 1.0"/>
    <parent link="base_link"/>
    <child link="pan_tilt_mount_link"/>
  </joint>
  <joint name="pan_tilt_base_joint" type="fixed">
    <origin rpy="0 0 0" xyz="0 0 0"/>
    <parent link="pan_tilt_mount_link"/>
    <child link="pan_tilt_base_link"/>
  </joint>
  <link name="pan_tilt_base_link">
    <inertial>
      <origin rpy="0 0 0" xyz="0 0 0.01"/>
      <mass value="0.1"/>
      <inertia ixx="0.0001" ixy="0" ixz="0" iyy="0.0001" iyz="0" izz="0.0001"/>
    </inertial>
    <visual>
      <origin rpy="0 0 -1.5707963267948966" xyz="0 0 0"/>
      <geometry>
        <mesh filename="file:///home/windiff/Code/Affordance-Guided-Interaction/assets/robot/meshes/pan_tilt/base.stl"/>
      </geometry>
      <material name="">
        <color rgba="0.2 0.2 0.2 1"/>
      </material>
    </visual>
    <collision>
      <origin rpy="0 0 0" xyz="0 0 0.01"/>
      <geometry>
        <cylinder length="0.023" radius="0.03"/>
      </geometry>
    </collision>
  </link>
  <link name="pan_tilt_yaw_link">
    <inertial>
      <origin rpy="0 0 0" xyz="0 0 0.03"/>
      <mass value="0.08"/>
      <inertia ixx="0.0001" ixy="0" ixz="0" iyy="0.0001" iyz="0" izz="0.0001"/>
    </inertial>
    <visual>
      <origin rpy="0 0 -1.5707963267948966" xyz="0 0 0"/>
      <geometry>
        <mesh filename="file:///home/windiff/Code/Affordance-Guided-Interaction/assets/robot/meshes/pan_tilt/yaw.stl"/>
      </geometry>
      <material name="">
        <color rgba="0.2 0.2 0.2 1"/>
      </material>
    </visual>
    <collision>
      <origin rpy="0 0 0" xyz="0 0 0.03"/>
      <geometry>
        <cylinder length="0.062" radius="0.03"/>
      </geometry>
    </collision>
  </link>
  <joint name="pan_tilt_yaw_joint" type="revolute">
    <origin rpy="0.0 0.0 0.0" xyz="0.0 0.0 0.023"/>
    <parent link="pan_tilt_base_link"/>
    <child link="pan_tilt_yaw_link"/>
    <axis xyz="0 0 1"/>
    <limit effort="5.0" lower="-1.0471975511965976" upper="1.0471975511965976" velocity="0.5235987755982988"/>
    <dynamics damping="0.5" friction="0.1"/>
  </joint>
  <!-- Yaw Transmission for Gazebo -->
  <transmission name="pan_tilt_yaw_trans">
    <type>transmission_interface/SimpleTransmission</type>
    <joint name="pan_tilt_yaw_joint">
      <hardwareInterface>hardware_interface/PositionJointInterface</hardwareInterface>
    </joint>
    <actuator name="pan_tilt_yaw_motor">
      <hardwareInterface>hardware_interface/PositionJointInterface</hardwareInterface>
      <mechanicalReduction>1</mechanicalReduction>
    </actuator>
  </transmission>
  <link name="pan_tilt_pitch_link">
    <inertial>
      <origin rpy="0 0 0" xyz="0 0 0.016"/>
      <mass value="0.06"/>
      <inertia ixx="0.0001" ixy="0" ixz="0" iyy="0.0001" iyz="0" izz="0.0001"/>
    </inertial>
    <visual>
      <origin rpy="0 0 -1.5707963267948966" xyz="0 0 0"/>
      <geometry>
        <mesh filename="file:///home/windiff/Code/Affordance-Guided-Interaction/assets/robot/meshes/pan_tilt/pitch.stl"/>
      </geometry>
      <material name="">
        <color rgba="0.2 0.2 0.2 1"/>
      </material>
    </visual>
    <collision>
      <origin rpy="0 0 0" xyz="0 0 0.016"/>
      <geometry>
        <cylinder length="0.032" radius="0.03"/>
      </geometry>
    </collision>
  </link>
  <joint name="pan_tilt_pitch_joint" type="revolute">
    <origin rpy="0.0 0.0 0.0" xyz="0.0 0.0 0.062"/>
    <parent link="pan_tilt_yaw_link"/>
    <child link="pan_tilt_pitch_link"/>
    <axis xyz="0 1 0"/>
    <limit effort="5.0" lower="-1.0471975511965976" upper="1.0471975511965976" velocity="0.5235987755982988"/>
    <dynamics damping="0.5" friction="0.1"/>
  </joint>
  <!-- Pitch Transmission for Gazebo -->
  <transmission name="pan_tilt_pitch_trans">
    <type>transmission_interface/SimpleTransmission</type>
    <joint name="pan_tilt_pitch_joint">
      <hardwareInterface>hardware_interface/PositionJointInterface</hardwareInterface>
    </joint>
    <actuator name="pan_tilt_pitch_motor">
      <hardwareInterface>hardware_interface/PositionJointInterface</hardwareInterface>
      <mechanicalReduction>1</mechanicalReduction>
    </actuator>
  </transmission>
  <link name="pan_tilt_surface">
    <inertial>
      <origin rpy="0 0 0" xyz="0 0 0"/>
      <mass value="0.01"/>
      <inertia ixx="0.00001" ixy="0" ixz="0" iyy="0.00001" iyz="0" izz="0.00001"/>
    </inertial>
  </link>
  <joint name="pan_tilt_surface_joint" type="fixed">
    <origin rpy="0 0 0" xyz="0.0 0.0 0.032"/>
    <parent link="pan_tilt_pitch_link"/>
    <child link="pan_tilt_surface"/>
  </joint>
  <link name="camera_support_link">
    <inertial>
      <origin rpy="0 0 0" xyz="0 0 0.05"/>
      <mass value="0.05"/>
      <inertia ixx="0.00005" ixy="0" ixz="0" iyy="0.00005" iyz="0" izz="0.00001"/>
    </inertial>
    <visual>
      <origin rpy="0 0 0" xyz="0 0 0.05"/>
      <geometry>
        <cylinder length="0.1" radius="0.02"/>
      </geometry>
      <material name="arm_support_grey"/>
    </visual>
    <collision>
      <origin rpy="0 0 0" xyz="0 0 0.05"/>
      <geometry>
        <cylinder length="0.1" radius="0.02"/>
      </geometry>
    </collision>
  </link>
  <joint name="pan_tilt_camera_support_joint" type="fixed">
    <origin rpy="0 0 0" xyz="0 0 0"/>
    <parent link="pan_tilt_surface"/>
    <child link="camera_support_link"/>
  </joint>
  <link name="head_d455_link">
    <visual>
      <geometry>
        <box size="0.02 0.09 0.025"/>
      </geometry>
      <material name="">
        <color rgba="0.1 0.1 0.1 1"/>
      </material>
    </visual>
    <collision>
      <geometry>
        <box size="0.02 0.09 0.025"/>
      </geometry>
    </collision>
    <inertial>
      <mass value="0.1"/>
      <inertia ixx="0.0001" ixy="0" ixz="0" iyy="0.0001" iyz="0" izz="0.0001"/>
    </inertial>
  </link>
  <joint name="head_d455_joint" type="fixed">
    <origin rpy="0 0 0" xyz="0 0 0.1"/>
    <parent link="camera_support_link"/>
    <child link="head_d455_link"/>
  </joint>
</robot>
