<?xml version="1.0"?>
<!-- 
  Z1 机械臂 Xacro Macro
  用途: 创建可复用的 Z1 机械臂，支持前缀和自定义父 link
  参数:
    - prefix: 关节和 link 名称前缀 (如 "left_" 或 "right_")
    - parent: 父 link 名称
    - origin_xyz / origin_rpy: 相对父 link 的位姿
    - UnitreeGripper: 是否包含夹爪 (true/false)
-->
<robot xmlns:xacro="http://www.ros.org/wiki/xacro">

  <!-- 引入 Z1 常量 -->
  <xacro:include filename="$(find z1_description)/xacro/const.xacro"/>

  <!-- 电机 transmission 宏 -->
  <xacro:macro name="z1_motorTransmission" params="prefix name">
    <transmission name="${prefix}trans_joint${name}">
      <type>transmission_interface/SimpleTransmission</type>
      <joint name="${prefix}joint${name}">
        <hardwareInterface>hardware_interface/PositionJointInterface</hardwareInterface>
      </joint>
      <actuator name="${prefix}motor${name}">
        <hardwareInterface>hardware_interface/PositionJointInterface</hardwareInterface>
        <mechanicalReduction>1</mechanicalReduction>
      </actuator>
    </transmission>
  </xacro:macro>

  <!-- Z1 机械臂主 macro -->
  <xacro:macro name="z1_arm" params="prefix parent *origin UnitreeGripper:=true">
    
    <!-- 基座连接到父 link -->
    <joint name="${prefix}base_joint" type="fixed">
      <xacro:insert_block name="origin"/>
      <parent link="${parent}"/>
      <child link="${prefix}link00"/>
    </joint>

    <!-- Link 00 - 底座 -->
    <link name="${prefix}link00">
      <visual>
        <origin rpy="0 0 0" xyz="0 0 0"/>
        <geometry>
          <mesh filename="package://z1_description/meshes/visual/z1_Link00.dae" scale="1 1 1"/>
        </geometry>
      </visual>
      <collision>
        <geometry>
          <cylinder length="${motor_height}" radius="${motor_diameter}"/>
        </geometry>
        <origin rpy="0 0 0" xyz="0 0 ${motor_height/2.0}"/>
      </collision>
      <inertial>
        <origin rpy="0 0 0" xyz="${L00_ComX} ${L00_ComY} ${L00_ComZ}"/>
        <mass value="${L00_Mass}"/>
        <inertia ixx="${L00_Ixx}" ixy="${L00_Ixy}" ixz="${L00_Ixz}"
                 iyy="${L00_Iyy}" iyz="${L00_Iyz}" izz="${L00_Izz}"/>
      </inertial>
    </link>

    <!-- Joint 1 -->
    <joint name="${prefix}joint1" type="revolute">
      <origin rpy="0 0 0" xyz="0 0 0.0585"/>
      <parent link="${prefix}link00"/>
      <child link="${prefix}link01"/>
      <axis xyz="0 0 1"/>
      <dynamics damping="${jointDamping}" friction="${jointFriction}"/>
      <limit effort="${torqueMax}" velocity="${velocityMax}" lower="${joint1_PositionMin}" upper="${joint1_PositionMax}"/>
    </joint>

    <!-- Link 01 -->
    <link name="${prefix}link01">
      <visual>
        <origin rpy="0 0 0" xyz="0 0 0"/>
        <geometry>
          <mesh filename="package://z1_description/meshes/visual/z1_Link01.dae" scale="1 1 1"/>
        </geometry>
      </visual>
      <collision>
        <origin rpy="0 0 0" xyz="0 0 0"/>
        <geometry>
          <mesh filename="package://z1_description/meshes/collision/z1_Link01.STL" scale="1 1 1"/>
        </geometry>
      </collision>
      <inertial>
        <origin rpy="0 0 0" xyz="${L01_ComX} ${L01_ComY} ${L01_ComZ}"/>
        <mass value="${L01_Mass}"/>
        <inertia ixx="${L01_Ixx}" ixy="${L01_Ixy}" ixz="${L01_Ixz}"
                 iyy="${L01_Iyy}" iyz="${L01_Iyz}" izz="${L01_Izz}"/>
      </inertial>
    </link>

    <!-- Joint 2 -->
    <joint name="${prefix}joint2" type="revolute">
      <origin rpy="0 0 0" xyz="0 0 0.045"/>
      <parent link="${prefix}link01"/>
      <child link="${prefix}link02"/>
      <axis xyz="0 1 0"/>
      <dynamics damping="${2*jointDamping}" friction="${2*jointFriction}"/>
      <limit effort="${2*torqueMax}" velocity="${velocityMax}" lower="${joint2_PositionMin}" upper="${joint2_PositionMax}"/>
    </joint>

    <!-- Link 02 -->
    <link name="${prefix}link02">
      <visual>
        <origin rpy="0 0 0" xyz="0 0 0"/>
        <geometry>
          <mesh filename="package://z1_description/meshes/visual/z1_Link02.dae" scale="1 1 1"/>
        </geometry>
      </visual>
      <collision>
        <geometry>
          <cylinder length="${2.0*motor_height}" radius="${motor_diameter}"/>
        </geometry>
        <origin rpy="${PI/2.0} 0 0" xyz="0 0 0"/>
      </collision>
      <collision>
        <geometry>
          <cylinder length="${arm1_height}" radius="${arm1_diameter}"/>
        </geometry>
        <origin rpy="0 ${PI/2.0} 0" xyz="${-0.045-arm1_height/2.0} 0 0"/>
      </collision>
      <collision>
        <geometry>
          <cylinder length="${motor_height}" radius="${motor_diameter}"/>
        </geometry>
        <origin rpy="${PI/2.0} 0 0" xyz="-0.35 0 0"/>
      </collision>
      <inertial>
        <origin rpy="0 0 0" xyz="${L02_ComX} ${L02_ComY} ${L02_ComZ}"/>
        <mass value="${L02_Mass}"/>
        <inertia ixx="${L02_Ixx}" ixy="${L02_Ixy}" ixz="${L02_Ixz}"
                 iyy="${L02_Iyy}" iyz="${L02_Iyz}" izz="${L02_Izz}"/>
      </inertial>
    </link>

    <!-- Joint 3 -->
    <joint name="${prefix}joint3" type="revolute">
      <origin rpy="0 0 0" xyz="-0.35 0 0"/>
      <parent link="${prefix}link02"/>
      <child link="${prefix}link03"/>
      <axis xyz="0 1 0"/>
      <dynamics damping="${jointDamping}" friction="${jointFriction}"/>
      <limit effort="${torqueMax}" velocity="${velocityMax}" lower="${joint3_PositionMin}" upper="${joint3_PositionMax}"/>
    </joint>

    <!-- Link 03 -->
    <link name="${prefix}link03">
      <visual>
        <origin rpy="0 0 0" xyz="0 0 0"/>
        <geometry>
          <mesh filename="package://z1_description/meshes/visual/z1_Link03.dae" scale="1 1 1"/>
        </geometry>
      </visual>
      <collision>
        <geometry>
          <cylinder length="${arm2_height-0.01}" radius="${arm2_diameter}"/>
        </geometry>
        <origin rpy="0 ${PI/2.0} 0" xyz="${0.065+arm2_height/2.0} 0 0.055"/>
      </collision>
      <collision>
        <geometry>
          <cylinder length="0.059" radius="${motor_diameter}"/>
        </geometry>
        <origin rpy="0 ${PI/2.0} ${PI/2.0}" xyz="${0.065+0.185-0.059/2.0} 0 0.055"/>
      </collision>
      <inertial>
        <origin rpy="0 0 0" xyz="${L03_ComX} ${L03_ComY} ${L03_ComZ}"/>
        <mass value="${L03_Mass}"/>
        <inertia ixx="${L03_Ixx}" ixy="${L03_Ixy}" ixz="${L03_Ixz}"
                 iyy="${L03_Iyy}" iyz="${L03_Iyz}" izz="${L03_Izz}"/>
      </inertial>
    </link>

    <!-- Joint 4 -->
    <joint name="${prefix}joint4" type="revolute">
      <origin rpy="0 0 0" xyz="0.218 0 0.057"/>
      <parent link="${prefix}link03"/>
      <child link="${prefix}link04"/>
      <axis xyz="0 1 0"/>
      <dynamics damping="${jointDamping}" friction="${jointFriction}"/>
      <limit effort="${torqueMax}" velocity="${velocityMax}" lower="${joint4_PositionMin}" upper="${joint4_PositionMax}"/>
    </joint>

    <!-- Link 04 -->
    <link name="${prefix}link04">
      <visual>
        <origin rpy="0 0 0" xyz="0 0 0"/>
        <geometry>
          <mesh filename="package://z1_description/meshes/visual/z1_Link04.dae" scale="1 1 1"/>
        </geometry>
      </visual>
      <collision>
        <geometry>
          <cylinder length="${motor_height + 2*0.008}" radius="${motor_diameter}"/>
        </geometry>
        <origin rpy="0 0 0" xyz="0.072 0 0"/>
      </collision>
      <inertial>
        <origin rpy="0 0 0" xyz="${L04_ComX} ${L04_ComY} ${L04_ComZ}"/>
        <mass value="${L04_Mass}"/>
        <inertia ixx="${L04_Ixx}" ixy="${L04_Ixy}" ixz="${L04_Ixz}"
                 iyy="${L04_Iyy}" iyz="${L04_Iyz}" izz="${L04_Izz}"/>
      </inertial>
    </link>

    <!-- Joint 5 -->
    <joint name="${prefix}joint5" type="revolute">
      <origin rpy="0 0 0" xyz="0.07 0.0 0.0"/>
      <parent link="${prefix}link04"/>
      <child link="${prefix}link05"/>
      <axis xyz="0 0 1"/>
      <dynamics damping="${jointDamping}" friction="${jointFriction}"/>
      <limit effort="${torqueMax}" velocity="${velocityMax}" lower="${joint5_PositionMin}" upper="${joint5_PositionMax}"/>
    </joint>

    <!-- Link 05 -->
    <link name="${prefix}link05">
      <visual>
        <origin rpy="0 0 0" xyz="0 0 0"/>
        <geometry>
          <mesh filename="package://z1_description/meshes/visual/z1_Link05.dae" scale="1 1 1"/>
        </geometry>
      </visual>
      <collision>
        <origin rpy="0 0 0" xyz="0 0 0"/>
        <geometry>
          <mesh filename="package://z1_description/meshes/collision/z1_Link05.STL" scale="1 1 1"/>
        </geometry>
      </collision>
      <inertial>
        <origin rpy="0 0 0" xyz="${L05_ComX} ${L05_ComY} ${L05_ComZ}"/>
        <mass value="${L05_Mass}"/>
        <inertia ixx="${L05_Ixx}" ixy="${L05_Ixy}" ixz="${L05_Ixz}"
                 iyy="${L05_Iyy}" iyz="${L05_Iyz}" izz="${L05_Izz}"/>
      </inertial>
    </link>

    <!-- Joint 6 -->
    <joint name="${prefix}joint6" type="revolute">
      <origin rpy="0 0 0" xyz="0.0492 0.0 0.0"/>
      <parent link="${prefix}link05"/>
      <child link="${prefix}link06"/>
      <axis xyz="1 0 0"/>
      <dynamics damping="${jointDamping}" friction="${jointFriction}"/>
      <limit effort="${torqueMax}" velocity="${velocityMax}" lower="${joint6_PositionMin}" upper="${joint6_PositionMax}"/>
    </joint>

    <!-- Link 06 -->
    <link name="${prefix}link06">
      <visual>
        <origin rpy="0 0 0" xyz="0 0 0"/>
        <geometry>
          <mesh filename="package://z1_description/meshes/visual/z1_Link06.dae" scale="1 1 1"/>
        </geometry>
      </visual>
      <collision>
        <geometry>
          <cylinder length="${motor_height}" radius="${motor_diameter}"/>
        </geometry>
        <origin rpy="0 ${PI/2.0} 0" xyz="${motor_height/2.0} 0 0"/>
      </collision>
      <inertial>
        <origin rpy="0 0 0" xyz="${L06_ComX} ${L06_ComY} ${L06_ComZ}"/>
        <mass value="${L06_Mass}"/>
        <inertia ixx="${L06_Ixx}" ixy="${L06_Ixy}" ixz="${L06_Ixz}"
                 iyy="${L06_Iyy}" iyz="${L06_Iyz}" izz="${L06_Izz}"/>
      </inertial>
    </link>

    <!-- Unitree Gripper (可选) -->
    <xacro:if value="${UnitreeGripper}">
      <joint name="${prefix}gripperStator_joint" type="fixed">
        <origin rpy="0 0 0" xyz="0.051 0.0 0.0"/>
        <parent link="${prefix}link06"/>
        <child link="${prefix}gripperStator"/>
      </joint>

      <link name="${prefix}gripperStator">
        <visual>
          <geometry>
            <mesh filename="package://z1_description/meshes/visual/z1_GripperStator.dae" scale="1 1 1"/>
          </geometry>
        </visual>
        <collision>
          <geometry>
            <mesh filename="package://z1_description/meshes/collision/z1_GripperStator.STL" scale="1 1 1"/>
          </geometry>
        </collision>
        <inertial>
          <origin rpy="0 0 0" xyz="${GripperStator_ComX} ${GripperStator_ComY} ${GripperStator_ComZ}"/>
          <mass value="${GripperStator_Mass}"/>
          <inertia ixx="${GripperStator_Ixx}" ixy="${GripperStator_Ixy}" ixz="${GripperStator_Ixz}"
                   iyy="${GripperStator_Iyy}" iyz="${GripperStator_Iyz}" izz="${GripperStator_Izz}"/>
        </inertial>
      </link>

      <joint name="${prefix}jointGripper" type="revolute">
        <origin rpy="0 0 0" xyz="0.049 0.0 0"/>
        <parent link="${prefix}gripperStator"/>
        <child link="${prefix}gripperMover"/>
        <axis xyz="0 1 0"/>
        <dynamics damping="${jointDamping}" friction="${jointFriction}"/>
        <limit effort="${torqueMax}" velocity="${velocityMax}" lower="${Gripper_PositionMin}" upper="${Gripper_PositionMax}"/>
      </joint>

      <link name="${prefix}gripperMover">
        <visual>
          <geometry>
            <mesh filename="package://z1_description/meshes/visual/z1_GripperMover.dae" scale="1 1 1"/>
          </geometry>
        </visual>
        <collision>
          <geometry>
            <mesh filename="package://z1_description/meshes/collision/z1_GripperMover.STL" scale="1 1 1"/>
          </geometry>
        </collision>
        <inertial>
          <origin rpy="0 0 0" xyz="${GripperMover_ComX} ${GripperMover_ComY} ${GripperMover_ComZ}"/>
          <mass value="${GripperMover_Mass}"/>
          <inertia ixx="${GripperMover_Ixx}" ixy="${GripperMover_Ixy}" ixz="${GripperMover_Ixz}"
                   iyy="${GripperMover_Iyy}" iyz="${GripperMover_Iyz}" izz="${GripperMover_Izz}"/>
        </inertial>
      </link>

      <xacro:z1_motorTransmission prefix="${prefix}" name="Gripper"/>

      <gazebo reference="${prefix}gripperStator">
        <self_collide>true</self_collide>
      </gazebo>

      <gazebo reference="${prefix}gripperMover">
        <self_collide>true</self_collide>
      </gazebo>
    </xacro:if>

    <!-- Transmissions -->
    <xacro:z1_motorTransmission prefix="${prefix}" name="1"/>
    <xacro:z1_motorTransmission prefix="${prefix}" name="2"/>
    <xacro:z1_motorTransmission prefix="${prefix}" name="3"/>
    <xacro:z1_motorTransmission prefix="${prefix}" name="4"/>
    <xacro:z1_motorTransmission prefix="${prefix}" name="5"/>
    <xacro:z1_motorTransmission prefix="${prefix}" name="6"/>

    <!-- Enable self-collision in Gazebo for arm links -->
    <gazebo reference="${prefix}link00">
      <self_collide>true</self_collide>
    </gazebo>
    <gazebo reference="${prefix}link01">
      <self_collide>true</self_collide>
    </gazebo>
    <gazebo reference="${prefix}link02">
      <self_collide>true</self_collide>
    </gazebo>
    <gazebo reference="${prefix}link03">
      <self_collide>true</self_collide>
    </gazebo>
    <gazebo reference="${prefix}link04">
      <self_collide>true</self_collide>
    </gazebo>
    <gazebo reference="${prefix}link05">
      <self_collide>true</self_collide>
    </gazebo>
    <gazebo reference="${prefix}link06">
      <self_collide>true</self_collide>
    </gazebo>

  </xacro:macro>

</robot>
